Workbook

Sheet Resumo
C1: Cliente: DENSO Projeto: APLICAÇÃO AUTOMÁTICA DE ETIQUETA
A2: # | B2: RUBRICAS | C2: VALOR | D2: % | E2: EXECUÇÃO (MESES)
E3: 1 | F3: 2 | G3: 3 | H3: 4 | I3: 5 | J3: 6 | K3: 7 | L3: 8 | M3: 9 | N3: 10 | O3: 11 | P3: 12 | Q3: 13 | R3: 14 | S3: 15 | T3: 16 | U3: 17 | V3: 18 | W3: 19 | X3: 20 | Y3: 21 | Z3: 22 | AA3: 23
A4: 1 | B4: Programas de Computador, Maq e Equip. | C4: =SUM(E4:AA4) -> 340084.8 | D4: =IFERROR(C4/$C$21,0) -> 0.094797678 | E4: =SUMIFS(tbRubrica[Custo Total],tbRubrica[Rubrica],Configuração!$A$2,tbRubrica[Mês],E$3)+SUMIFS(tbRubrica[Custo Total],tbRubrica[Rubrica],Configuração!$A$3,tbRubrica[Mês],E$3) -> 340084.8 | F4: =SUMIFS(tbRubrica[Custo Total],tbRubrica[Rubrica],Configuração!$A$2,tbRubrica[Mês],F$3)+SUMIFS(tbRubrica[Custo Total],tbRubrica[Rubrica],Configuração!$A$3,tbRubrica[Mês],F$3) -> 0 | G4: =SUMIFS(tbRubrica[Custo Total],tbRubrica[Rubrica],Configuração!$A$2,tbRubrica[Mês],G$3)+SUMIFS(tbRubrica[Custo Total],tbRubrica[Rubrica],Configuração!$A$3,tbRubrica[Mês],G$3) -> 0 | H4: =SUMIFS(tbRubrica[Custo Total],tbRubrica[Rubrica],Configuração!$A$2,tbRubrica[Mês],H$3)+SUMIFS(tbRubrica[Custo Total],tbRubrica[Rubrica],Configuração!$A$3,tbRubrica[Mês],H$3) -> 0 | I4: =SUMIFS(tbRubrica[Custo Total],tbRubrica[Rubrica],Configuração!$A$2,tbRubrica[Mês],I$3)+SUMIFS(tbRubrica[Custo Total],tbRubrica[Rubrica],Configuração!$A$3,tbRubrica[Mês],I$3) -> 0 | J4: =SUMIFS(tbRubrica[Custo Total],tbRubrica[Rubrica],Configuração!$A$2,tbRubrica[Mês],J$3)+SUMIFS(tbRubrica[Custo Total],tbRubrica[Rubrica],Configuração!$A$3,tbRubrica[Mês],J$3) -> 0 | K4: =SUMIFS(tbRubrica[Custo Total],tbRubrica[Rubrica],Configuração!$A$2,tbRubrica[Mês],K$3)+SUMIFS(tbRubrica[Custo Total],tbRubrica[Rubrica],Configuração!$A$3,tbRubrica[Mês],K$3) -> 0 | L4: =SUMIFS(tbRubrica[Custo Total],tbRubrica[Rubrica],Configuração!$A$2,tbRubrica[Mês],L$3)+SUMIFS(tbRubrica[Custo Total],tbRubrica[Rubrica],Configuração!$A$3,tbRubrica[Mês],L$3) -> 0 | ... AA4: =SUMIFS(tbRubrica[Custo Total],tbRubrica[Rubrica],Configuração!$A$2,tbRubrica[Mês],AA$3)+SUMIFS(tbRubrica[Custo Total],tbRubrica[Rubrica],Configuração!$A$3,tbRubrica[Mês],AA$3) -> 0 | AE4: =SUM(AF6:AQ6)/12 -> 69161.305
A5: 2 | B5: Implant., Ampliação ou Moderniz. | C5: =SUM(E5:AA5) -> 0 | D5: =IFERROR(C5/$C$21,0) -> 0 | E5: =SUMIFS(tbRubrica[Custo Total],tbRubrica[Rubrica],Configuração!$A$4,tbRubrica[Mês],E$3) -> 0 | F5: =SUMIFS(tbRubrica[Custo Total],tbRubrica[Rubrica],Configuração!$A$4,tbRubrica[Mês],F$3) -> 0 | G5: =SUMIFS(tbRubrica[Custo Total],tbRubrica[Rubrica],Configuração!$A$4,tbRubrica[Mês],G$3) -> 0 | H5: =SUMIFS(tbRubrica[Custo Total],tbRubrica[Rubrica],Configuração!$A$4,tbRubrica[Mês],H$3) -> 0 | I5: =SUMIFS(tbRubrica[Custo Total],tbRubrica[Rubrica],Configuração!$A$4,tbRubrica[Mês],I$3) -> 0 | J5: =SUMIFS(tbRubrica[Custo Total],tbRubrica[Rubrica],Configuração!$A$4,tbRubrica[Mês],J$3) -> 0 | K5: =SUMIFS(tbRubrica[Custo Total],tbRubrica[Rubrica],Configuração!$A$4,tbRubrica[Mês],K$3) -> 0 | L5: =SUMIFS(tbRubrica[Custo Total],tbRubrica[Rubrica],Configuração!$A$4,tbRubrica[Mês],L$3) -> 0 | ... V5: =SUMIFS(tbRubrica[Custo Total],tbRubrica[Rubrica],Configuração!$A$4,tbRubrica[Mês],V$3) -> 0 | W5: =SUMIFS(tbEquipe[Custo],tbEquipe[Tipo],Configuração!$F$2,tbEquipe[Mês],W$3) -> 0 | X5: =SUMIFS(tbEquipe[Custo],tbEquipe[Tipo],Configuração!$F$2,tbEquipe[Mês],X$3) -> 0 | Y5: =SUMIFS(tbEquipe[Custo],tbEquipe[Tipo],Configuração!$F$2,tbEquipe[Mês],Y$3) -> 0 | Z5: =SUMIFS(tbEquipe[Custo],tbEquipe[Tipo],Configuração!$F$2,tbEquipe[Mês],Z$3) -> 0 | AA5: =SUMIFS(tbEquipe[Custo],tbEquipe[Tipo],Configuração!$F$2,tbEquipe[Mês],AA$3) -> 0 | AE5: =SUM(AF7:AQ7)/12 -> 14523.874
A6: 3.1 | B6: Recursos Humanos Diretos | C6: =SUM(E6:AA6) -> 847815.23 | D6: =IFERROR(C6/$C$21,0) -> 0.2363261 | E6: =SUMIFS(tbEquipe[Custo],tbEquipe[Tipo],Configuração!$F$2,tbEquipe[Mês],E$3)+SUMIFS(tbEquipe[Custo],tbEquipe[Tipo],Configuração!$F$4,tbEquipe[Mês],E$3) -> 67089.43 | F6: =SUMIFS(tbEquipe[Custo],tbEquipe[Tipo],Configuração!$F$2,tbEquipe[Mês],F$3)+SUMIFS(tbEquipe[Custo],tbEquipe[Tipo],Configuração!$F$4,tbEquipe[Mês],F$3) -> 69436.33 | G6: =SUMIFS(tbEquipe[Custo],tbEquipe[Tipo],Configuração!$F$2,tbEquipe[Mês],G$3)+SUMIFS(tbEquipe[Custo],tbEquipe[Tipo],Configuração!$F$4,tbEquipe[Mês],G$3) -> 69436.33 | H6: =SUMIFS(tbEquipe[Custo],tbEquipe[Tipo],Configuração!$F$2,tbEquipe[Mês],H$3)+SUMIFS(tbEquipe[Custo],tbEquipe[Tipo],Configuração!$F$4,tbEquipe[Mês],H$3) -> 69436.33 | I6: =SUMIFS(tbEquipe[Custo],tbEquipe[Tipo],Configuração!$F$2,tbEquipe[Mês],I$3)+SUMIFS(tbEquipe[Custo],tbEquipe[Tipo],Configuração!$F$4,tbEquipe[Mês],I$3) -> 69436.33 | J6: =SUMIFS(tbEquipe[Custo],tbEquipe[Tipo],Configuração!$F$2,tbEquipe[Mês],J$3)+SUMIFS(tbEquipe[Custo],tbEquipe[Tipo],Configuração!$F$4,tbEquipe[Mês],J$3) -> 69436.33 | K6: =SUMIFS(tbEquipe[Custo],tbEquipe[Tipo],Configuração!$F$2,tbEquipe[Mês],K$3)+SUMIFS(tbEquipe[Custo],tbEquipe[Tipo],Configuração!$F$4,tbEquipe[Mês],K$3) -> 69436.33 | L6: =SUMIFS(tbEquipe[Custo],tbEquipe[Tipo],Configuração!$F$2,tbEquipe[Mês],L$3)+SUMIFS(tbEquipe[Custo],tbEquipe[Tipo],Configuração!$F$4,tbEquipe[Mês],L$3) -> 69436.33 | ... AA6: =SUMIFS(tbEquipe[Custo],tbEquipe[Tipo],Configuração!$F$2,tbEquipe[Mês],AA$3)+SUMIFS(tbEquipe[Custo],tbEquipe[Tipo],Configuração!$F$4,tbEquipe[Mês],AA$3) -> 0 | AD6: Recursos Humanos Diretos | AE6: 829935.65 | AF6: 92476.046 | AG6: 105351.37 | AH6: 105351.37 | AI6: 105351.37 | AJ6: 105351.37 | AK6: 105351.37 | AL6: 105351.37 | AM6: 105351.37 | AN6: 0 | AO6: 0 | AP6: 0 | AQ6: 0 | AS6: =SUM(AF6:AQ6)-C6 -> -17879.58
A7: 3.2 | B7: Recursos Humanos Indiretos | C7: =SUM(E7:AA7) -> 169563.05 | D7: =IFERROR(C7/$C$21,0) -> 0.04726522 | E7: =SUMIFS(tbEquipe[Custo],tbEquipe[Tipo],Configuração!$F$3,tbEquipe[Mês],E$3)+SUM(tbRHI[1]) -> 13417.886 | F7: =SUMIFS(tbEquipe[Custo],tbEquipe[Tipo],Configuração!$F$3,tbEquipe[Mês],F$3)+SUM(tbRHI[2]) -> 13887.266 | G7: =SUMIFS(tbEquipe[Custo],tbEquipe[Tipo],Configuração!$F$3,tbEquipe[Mês],G$3)+SUM(tbRHI[3]) -> 13887.266 | H7: =SUMIFS(tbEquipe[Custo],tbEquipe[Tipo],Configuração!$F$3,tbEquipe[Mês],H$3)+SUM(tbRHI[4]) -> 13887.266 | I7: =SUMIFS(tbEquipe[Custo],tbEquipe[Tipo],Configuração!$F$3,tbEquipe[Mês],I$3)+SUM(tbRHI[5]) -> 13887.266 | J7: =SUMIFS(tbEquipe[Custo],tbEquipe[Tipo],Configuração!$F$3,tbEquipe[Mês],J$3)+SUM(tbRHI[6]) -> 13887.266 | K7: =SUMIFS(tbEquipe[Custo],tbEquipe[Tipo],Configuração!$F$3,tbEquipe[Mês],K$3)+SUM(tbRHI[7]) -> 13887.266 | L7: =SUMIFS(tbEquipe[Custo],tbEquipe[Tipo],Configuração!$F$3,tbEquipe[Mês],L$3)+SUM(tbRHI[8]) -> 13887.266 | M7: =SUMIFS(tbEquipe[Custo],tbEquipe[Tipo],Configuração!$F$3,tbEquipe[Mês],M$3)+SUM(tbRHI[9]) -> 13887.266 | N7: =SUMIFS(tbEquipe[Custo],tbEquipe[Tipo],Configuração!$F$3,tbEquipe[Mês],N$3)+SUM(tbRHI[10]) -> 13887.266 | O7: =SUMIFS(tbEquipe[Custo],tbEquipe[Tipo],Configuração!$F$3,tbEquipe[Mês],O$3)+SUM(tbRHI[11]) -> 13887.266 | P7: =SUMIFS(tbEquipe[Custo],tbEquipe[Tipo],Configuração!$F$3,tbEquipe[Mês],P$3)+SUM(tbRHI[12]) -> 13887.266 | Q7: =SUMIFS(tbEquipe[Custo],tbEquipe[Tipo],Configuração!$F$3,tbEquipe[Mês],Q$3)+SUM(tbRHI[13]) -> 1085.0114 | R7: =SUMIFS(tbEquipe[Custo],tbEquipe[Tipo],Configuração!$F$3,tbEquipe[Mês],R$3)+SUM(tbRHI[14]) -> 1150.1121 | S7: =SUMIFS(tbEquipe[Custo],tbEquipe[Tipo],Configuração!$F$3,tbEquipe[Mês],S$3)+SUM(tbRHI[15]) -> 1150.1121 | T7: =SUMIFS(tbEquipe[Custo],tbEquipe[Tipo],Configuração!$F$3,tbEquipe[Mês],T$3)+SUM(tbRHI[16]) -> 0 | U7: =SUMIFS(tbEquipe[Custo],tbEquipe[Tipo],Configuração!$F$3,tbEquipe[Mês],U$3)+SUM(tbRHI[17]) -> 0 | V7: =SUMIFS(tbEquipe[Custo],tbEquipe[Tipo],Configuração!$F$3,tbEquipe[Mês],V$3)+SUM(tbRHI[18]) -> 0 | W7: =SUMIFS(tbEquipe[Custo],tbEquipe[Tipo],Configuração!$F$3,tbEquipe[Mês],W$3)+SUM(tbRHI[19]) -> 0 | X7: =SUMIFS(tbEquipe[Custo],tbEquipe[Tipo],Configuração!$F$3,tbEquipe[Mês],X$3)+SUM(tbRHI[20]) -> 0 | Y7: =SUMIFS(tbEquipe[Custo],tbEquipe[Tipo],Configuração!$F$3,tbEquipe[Mês],Y$3)+SUM(tbRHI[21]) -> 0 | Z7: =SUMIFS(tbEquipe[Custo],tbEquipe[Tipo],Configuração!$F$3,tbEquipe[Mês],Z$3)+SUM(tbRHI[22]) -> 0 | AA7: =SUMIFS(tbEquipe[Custo],tbEquipe[Tipo],Configuração!$F$3,tbEquipe[Mês],AA$3)+SUM(tbRHI[23]) -> 0 | AD7: Recursos Humanos Indiretos | AE7: 174286.49 | AF7: 19419.97 | AG7: 22123.788 | AH7: 22123.788 | AI7: 22123.788 | AJ7: 22123.788 | AK7: 22123.788 | AL7: 22123.788 | AM7: 22123.788 | AN7: 0 | AO7: 0 | AP7: 0 | AQ7: 0 | AS7: =SUM(AF7:AQ7)-C7 -> 4723.4405
A8: 4 | B8: Serviço Técnico de Terceiros | C8: =SUM(E8:AA8) -> 390226.14 | D8: =IFERROR(C8/$C$21,0) -> 0.10877443 | E8: =SUMIFS(tbRubrica[Custo Total],tbRubrica[Rubrica],Configuração!$A$5,tbRubrica[Mês],E$3) -> 0 | F8: =SUMIFS(tbRubrica[Custo Total],tbRubrica[Rubrica],Configuração!$A$5,tbRubrica[Mês],F$3) -> 0 | G8: =SUMIFS(tbRubrica[Custo Total],tbRubrica[Rubrica],Configuração!$A$5,tbRubrica[Mês],G$3) -> 390226.14 | H8: =SUMIFS(tbRubrica[Custo Total],tbRubrica[Rubrica],Configuração!$A$5,tbRubrica[Mês],H$3) -> 0 | I8: =SUMIFS(tbRubrica[Custo Total],tbRubrica[Rubrica],Configuração!$A$5,tbRubrica[Mês],I$3) -> 0 | J8: =SUMIFS(tbRubrica[Custo Total],tbRubrica[Rubrica],Configuração!$A$5,tbRubrica[Mês],J$3) -> 0 | K8: =SUMIFS(tbRubrica[Custo Total],tbRubrica[Rubrica],Configuração!$A$5,tbRubrica[Mês],K$3) -> 0 | L8: =SUMIFS(tbRubrica[Custo Total],tbRubrica[Rubrica],Configuração!$A$5,tbRubrica[Mês],L$3) -> 0 | ... AA8: =SUMIFS(tbRubrica[Custo Total],tbRubrica[Rubrica],Configuração!$A$5,tbRubrica[Mês],AA$3) -> 0
A9: 5 | B9: Material de Consumo | C9: =SUM(E9:AA9) -> 720254.41 | D9: =IFERROR(C9/$C$21,0) -> 0.20076888 | E9: =SUMIFS(tbRubrica[Custo Total],tbRubrica[Rubrica],Configuração!$A$6,tbRubrica[Mês],E$3) -> 0 | F9: =SUMIFS(tbRubrica[Custo Total],tbRubrica[Rubrica],Configuração!$A$6,tbRubrica[Mês],F$3) -> 720254.41 | G9: =SUMIFS(tbRubrica[Custo Total],tbRubrica[Rubrica],Configuração!$A$6,tbRubrica[Mês],G$3) -> 0 | H9: =SUMIFS(tbRubrica[Custo Total],tbRubrica[Rubrica],Configuração!$A$6,tbRubrica[Mês],H$3) -> 0 | I9: =SUMIFS(tbRubrica[Custo Total],tbRubrica[Rubrica],Configuração!$A$6,tbRubrica[Mês],I$3) -> 0 | J9: =SUMIFS(tbRubrica[Custo Total],tbRubrica[Rubrica],Configuração!$A$6,tbRubrica[Mês],J$3) -> 0 | K9: =SUMIFS(tbRubrica[Custo Total],tbRubrica[Rubrica],Configuração!$A$6,tbRubrica[Mês],K$3) -> 0 | L9: =SUMIFS(tbRubrica[Custo Total],tbRubrica[Rubrica],Configuração!$A$6,tbRubrica[Mês],L$3) -> 0 | ... AA9: =SUMIFS(tbRubrica[Custo Total],tbRubrica[Rubrica],Configuração!$A$6,tbRubrica[Mês],AA$3) -> 0 | AE9: =SUM(AF11:AQ11)/12 -> 18493.443
B10: SUB-TOTAL 1 | C10: =SUM(C4:C9) -> 2467943.6 | D10: =IFERROR(C10/$C$21,0) -> 0.68793231 | E10: =SUM(E4:E9) -> 420592.12 | F10: =SUM(F4:F9) -> 803578.01 | G10: =SUM(G4:G9) -> 473549.74 | H10: =SUM(H4:H9) -> 83323.596 | I10: =SUM(I4:I9) -> 83323.596 | J10: =SUM(J4:J9) -> 83323.596 | K10: =SUM(K4:K9) -> 83323.596 | L10: =SUM(L4:L9) -> 83323.596 | ... AA10: =SUM(AA4:AA9) -> 0
A11: 6.1 | B11: =Configuração!A7 -> Outros correlatos | C11: =SUM(E11:AA11) -> 222666.6 | D11: =IFERROR(C11/$C$21,0) -> 0.062067686 | E11: =SUMIFS(tbRubrica[Custo Total],tbRubrica[Rubrica],Configuração!$A$7,tbRubrica[Mês],E$3)+SUM(tbRateio[1]) -> 110059.96 | F11: =SUMIFS(tbRubrica[Observações],tbRubrica[Descrição],Configuração!$A$7,tbRubrica[Quantidade],F$3)+SUM(tbRateio[2]) -> 10102.461 | G11: =SUMIFS(tbRubrica[Coluna1],tbRubrica[Justificativa],Configuração!$A$7,tbRubrica[Custo Unitário],G$3)+SUM(tbRateio[3]) -> 10102.461 | H11: =SUMIFS(tbRubrica[Rubrica],tbRubrica[Mês],Configuração!$A$7,tbRubrica[Frete],H$3)+SUM(tbRateio[4]) -> 10102.461 | I11: =SUMIFS(tbRubrica[Descrição],tbRubrica[Quantidade],Configuração!$A$7,tbRubrica[Custo Total],I$3)+SUM(tbRateio[5]) -> 10102.461 | J11: =SUMIFS(tbRubrica[Justificativa],tbRubrica[Custo Unitário],Configuração!$A$7,tbRubrica[Observações],J$3)+SUM(tbRateio[6]) -> 10102.461 | K11: =SUMIFS(tbRubrica[Mês],tbRubrica[Frete],Configuração!$A$7,tbRubrica[Coluna1],K$3)+SUM(tbRateio[7]) -> 10102.461 | L11: =SUMIFS(tbRubrica[Quantidade],tbRubrica[Custo Total],Configuração!$A$7,tbRubrica[Rubrica],L$3)+SUM(tbRateio[8]) -> 10102.461 | M11: =SUMIFS(tbRubrica[Custo Unitário],tbRubrica[Observações],Configuração!$A$7,tbRubrica[Descrição],M$3)+SUM(tbRateio[9]) -> 10102.461 | N11: =SUMIFS(tbRubrica[Frete],tbRubrica[Coluna1],Configuração!$A$7,tbRubrica[Justificativa],N$3)+SUM(tbRateio[10]) -> 10102.461 | O11: =SUMIFS(tbRubrica[Custo Total],tbRubrica[Rubrica],Configuração!$A$7,tbRubrica[Mês],O$3)+SUM(tbRateio[11]) -> 10102.461 | P11: =SUMIFS(tbRubrica[Observações],tbRubrica[Descrição],Configuração!$A$7,tbRubrica[Quantidade],P$3)+SUM(tbRateio[12]) -> 10102.461 | Q11: =SUMIFS(tbRubrica[Coluna1],tbRubrica[Justificativa],Configuração!$A$7,tbRubrica[Custo Unitário],Q$3)+SUM(tbRateio[13]) -> 489.2604 | R11: =SUMIFS(tbRubrica[Rubrica],tbRubrica[Mês],Configuração!$A$7,tbRubrica[Frete],R$3)+SUM(tbRateio[14]) -> 495.15565 | S11: =SUMIFS(tbRubrica[Descrição],tbRubrica[Quantidade],Configuração!$A$7,tbRubrica[Custo Total],S$3)+SUM(tbRateio[15]) -> 495.15565 | T11: =SUMIFS(tbRubrica[Custo Total],tbRubrica[Rubrica],Configuração!$A$7,tbRubrica[Mês],T$3)+SUM(tbRateio[16]) -> 0 | U11: =SUMIFS(tbRubrica[Custo Total],tbRubrica[Rubrica],Configuração!$A$7,tbRubrica[Mês],U$3)+SUM(tbRateio[17]) -> 0 | V11: =SUMIFS(tbRubrica[Custo Total],tbRubrica[Rubrica],Configuração!$A$7,tbRubrica[Mês],V$3)+SUM(tbRateio[18]) -> 0 | W11: =SUMIFS(tbRubrica[Custo Total],tbRubrica[Rubrica],Configuração!$A$7,tbRubrica[Mês],W$3)+SUM(tbRateio[19]) -> 0 | X11: =SUMIFS(tbRubrica[Custo Total],tbRubrica[Rubrica],Configuração!$A$7,tbRubrica[Mês],X$3)+SUM(tbRateio[20]) -> 0 | Y11: =SUMIFS(tbRubrica[Custo Total],tbRubrica[Rubrica],Configuração!$A$7,tbRubrica[Mês],Y$3)+SUM(tbRateio[21]) -> 0 | Z11: =SUMIFS(tbRubrica[Custo Total],tbRubrica[Rubrica],Configuração!$A$7,tbRubrica[Mês],Z$3)+SUM(tbRateio[22]) -> 0 | AA11: =SUMIFS(tbRubrica[Custo Total],tbRubrica[Rubrica],Configuração!$A$7,tbRubrica[Mês],AA$3)+SUM(tbRateio[23]) -> 0 | AD11: Outros correlatos | AE11: 291921.32 | AF11: 113606.08 | AG11: 15473.605 | AH11: 15473.605 | AI11: 15473.605 | AJ11: 15473.605 | AK11: 15473.605 | AL11: 15473.605 | AM11: 15473.605 | AN11: 0 | AO11: 0 | AP11: 0 | AQ11: 0 | AS11: =SUM(AF11:AQ11)-C11 -> -745.28404
A12: 6.2 | B12: =Configuração!A8 -> Treinamentos | C12: =SUM(E12:AA12) -> 0 | D12: =IFERROR(C12/$C$21,0) -> 0 | E12: =SUMIFS(tbRubrica[Custo Total],tbRubrica[Rubrica],Configuração!$A$8,tbRubrica[Mês],E$3) -> 0 | F12: =SUMIFS(tbRubrica[Custo Total],tbRubrica[Rubrica],Configuração!$A$8,tbRubrica[Mês],F$3) -> 0 | G12: =SUMIFS(tbRubrica[Custo Total],tbRubrica[Rubrica],Configuração!$A$8,tbRubrica[Mês],G$3) -> 0 | H12: =SUMIFS(tbRubrica[Custo Total],tbRubrica[Rubrica],Configuração!$A$8,tbRubrica[Mês],H$3) -> 0 | I12: =SUMIFS(tbRubrica[Custo Total],tbRubrica[Rubrica],Configuração!$A$8,tbRubrica[Mês],I$3) -> 0 | J12: =SUMIFS(tbRubrica[Custo Total],tbRubrica[Rubrica],Configuração!$A$8,tbRubrica[Mês],J$3) -> 0 | K12: =SUMIFS(tbRubrica[Custo Total],tbRubrica[Rubrica],Configuração!$A$8,tbRubrica[Mês],K$3) -> 0 | L12: =SUMIFS(tbRubrica[Custo Total],tbRubrica[Rubrica],Configuração!$A$8,tbRubrica[Mês],L$3) -> 0 | ... AA12: =SUMIFS(tbRubrica[Custo Total],tbRubrica[Rubrica],Configuração!$A$8,tbRubrica[Mês],AA$3) -> 0
A13: 6.3 | B13: =Configuração!A9 -> Livros e Periódicos | C13: =SUM(E13:AA13) -> 0 | D13: =IFERROR(C13/$C$21,0) -> 0 | E13: =SUMIFS(tbRubrica[Custo Total],tbRubrica[Rubrica],Configuração!$A$9,tbRubrica[Mês],E$3) -> 0 | F13: =SUMIFS(tbRubrica[Custo Total],tbRubrica[Rubrica],Configuração!$A$9,tbRubrica[Mês],F$3) -> 0 | G13: =SUMIFS(tbRubrica[Custo Total],tbRubrica[Rubrica],Configuração!$A$9,tbRubrica[Mês],G$3) -> 0 | H13: =SUMIFS(tbRubrica[Custo Total],tbRubrica[Rubrica],Configuração!$A$9,tbRubrica[Mês],H$3) -> 0 | I13: =SUMIFS(tbRubrica[Custo Total],tbRubrica[Rubrica],Configuração!$A$9,tbRubrica[Mês],I$3) -> 0 | J13: =SUMIFS(tbRubrica[Custo Total],tbRubrica[Rubrica],Configuração!$A$9,tbRubrica[Mês],J$3) -> 0 | K13: =SUMIFS(tbRubrica[Custo Total],tbRubrica[Rubrica],Configuração!$A$9,tbRubrica[Mês],K$3) -> 0 | L13: =SUMIFS(tbRubrica[Custo Total],tbRubrica[Rubrica],Configuração!$A$9,tbRubrica[Mês],L$3) -> 0 | ... AA13: =SUMIFS(tbRubrica[Custo Total],tbRubrica[Rubrica],Configuração!$A$9,tbRubrica[Mês],AA$3) -> 0
A14: 6.4 | B14: =Configuração!A10 -> Viagens | C14: =SUM(E14:AA14) -> 0 | D14: =IFERROR(C14/$C$21,0) -> 0 | E14: =SUMIFS(tbRubrica[Custo Total],tbRubrica[Rubrica],Configuração!$A$10,tbRubrica[Mês],E$3) -> 0 | F14: =SUMIFS(tbRubrica[Custo Total],tbRubrica[Rubrica],Configuração!$A$10,tbRubrica[Mês],F$3) -> 0 | G14: =SUMIFS(tbRubrica[Custo Total],tbRubrica[Rubrica],Configuração!$A$10,tbRubrica[Mês],G$3) -> 0 | H14: =SUMIFS(tbRubrica[Custo Total],tbRubrica[Rubrica],Configuração!$A$10,tbRubrica[Mês],H$3) -> 0 | I14: =SUMIFS(tbRubrica[Custo Total],tbRubrica[Rubrica],Configuração!$A$10,tbRubrica[Mês],I$3) -> 0 | J14: =SUMIFS(tbRubrica[Custo Total],tbRubrica[Rubrica],Configuração!$A$10,tbRubrica[Mês],J$3) -> 0 | K14: =SUMIFS(tbRubrica[Custo Total],tbRubrica[Rubrica],Configuração!$A$10,tbRubrica[Mês],K$3) -> 0 | L14: =SUMIFS(tbRubrica[Custo Total],tbRubrica[Rubrica],Configuração!$A$10,tbRubrica[Mês],L$3) -> 0 | ... AA14: =SUMIFS(tbRubrica[Custo Total],tbRubrica[Rubrica],Configuração!$A$10,tbRubrica[Mês],AA$3) -> 0
A15: 6.5 | B15: ISSQN | C15: =SUM(E15:AA15) -> 179374.02 | D15: =IFERROR(C15/$C$21,0) -> 0.05 | E15: =SUM(E10:E14)/(1-SUM(Configuração!$D$2,Configuração!$D$5:$D$6))*Configuração!$D$5 -> 35376.805 | F15: =SUM(F10:F14)/(1-SUM(Configuração!$D$2,Configuração!$D$5:$D$6))*Configuração!$D$5 -> 54245.365 | G15: =SUM(G10:G14)/(1-SUM(Configuração!$D$2,Configuração!$D$5:$D$6))*Configuração!$D$5 -> 32243.48 | H15: =SUM(H10:H14)/(1-SUM(Configuração!$D$2,Configuração!$D$5:$D$6))*Configuração!$D$5 -> 6228.4038 | I15: =SUM(I10:I14)/(1-SUM(Configuração!$D$2,Configuração!$D$5:$D$6))*Configuração!$D$5 -> 6228.4038 | J15: =SUM(J10:J14)/(1-SUM(Configuração!$D$2,Configuração!$D$5:$D$6))*Configuração!$D$5 -> 6228.4038 | K15: =SUM(K10:K14)/(1-SUM(Configuração!$D$2,Configuração!$D$5:$D$6))*Configuração!$D$5 -> 6228.4038 | L15: =SUM(L10:L14)/(1-SUM(Configuração!$D$2,Configuração!$D$5:$D$6))*Configuração!$D$5 -> 6228.4038 | ... AA15: =SUM(AA10:AA14)/(1-SUM(Configuração!$D$2,Configuração!$D$5:$D$6))*Configuração!$D$5 -> 0
B16: SUB-TOTAL 2 | C16: =SUM(C11:C15) -> 402040.62 | D16: =IFERROR(C16/$C$21,0) -> 0.11206769 | E16: =SUM(E11:E15) -> 145436.76 | F16: =SUM(F11:F15) -> 64347.826 | G16: =SUM(G11:G15) -> 42345.941 | H16: =SUM(H11:H15) -> 16330.865 | I16: =SUM(I11:I15) -> 16330.865 | J16: =SUM(J11:J15) -> 16330.865 | K16: =SUM(K11:K15) -> 16330.865 | L16: =SUM(L11:L15) -> 16330.865 | ... AA16: =SUM(AA11:AA15) -> 0
B17: SUB-TOTAL DISPÊNDIOS | C17: =C10+C16 -> 2869984.3 | D17: =IFERROR(C17/$C$21,0) -> 0.8 | E17: =E10+E16 -> 566028.88 | F17: =F10+F16 -> 867925.83 | G17: =G10+G16 -> 515895.68 | H17: =H10+H16 -> 99654.461 | I17: =I10+I16 -> 99654.461 | J17: =J10+J16 -> 99654.461 | K17: =K10+K16 -> 99654.461 | L17: =L10+L16 -> 99654.461 | ... AA17: =AA10+AA16 -> 0
A18: 7 | B18: Custos Incorridos & Reserva de P&D | C18: =SUM(E18:AA18) -> 717496.06 | D18: =IFERROR(C18/C21,0) -> 0.2 | E18: =E19+E20 -> 141507.22 | F18: =F19+F20 -> 216981.46 | G18: =G19+G20 -> 128973.92 | H18: =H19+H20 -> 24913.615 | I18: =I19+I20 -> 24913.615 | J18: =J19+J20 -> 24913.615 | K18: =K19+K20 -> 24913.615 | L18: =L19+L20 -> 24913.615 | ... AA18: =AA19+AA20 -> 0
A19: 7.1 | B19: Custos Incorridos / Constituição de Reserva - Conecthus | C19: =SUM(E19:AA19) -> 717496.06 | D19: =IFERROR(C19/$AD$21,0) -> 0 | E19: =(E17/(1-SUM(Configuração!$D$2,Configuração!$D$6))*Configuração!$D$2) -> 141507.22 | F19: =(F17/(1-SUM(Configuração!$D$2,Configuração!$D$6))*Configuração!$D$2) -> 216981.46 | G19: =(G17/(1-SUM(Configuração!$D$2,Configuração!$D$6))*Configuração!$D$2) -> 128973.92 | H19: =(H17/(1-SUM(Configuração!$D$2,Configuração!$D$6))*Configuração!$D$2) -> 24913.615 | I19: =(I17/(1-SUM(Configuração!$D$2,Configuração!$D$6))*Configuração!$D$2) -> 24913.615 | J19: =(J17/(1-SUM(Configuração!$D$2,Configuração!$D$6))*Configuração!$D$2) -> 24913.615 | K19: =(K17/(1-SUM(Configuração!$D$2,Configuração!$D$6))*Configuração!$D$2) -> 24913.615 | L19: =(L17/(1-SUM(Configuração!$D$2,Configuração!$D$6))*Configuração!$D$2) -> 24913.615 | ... AA19: =(AA17/(1-SUM(Configuração!$D$2,Configuração!$D$6))*Configuração!$D$2) -> 0
A20: 7.2 | B20: Outros Custos Incorridos - CITS | C20: =SUM(E20:AA20) -> 0 | D20: =IFERROR(C20/$AD$21,0) -> 0 | E20: =(E17/(1-SUM(Configuração!$D$2,Configuração!$D$6)))*Configuração!$D$6 -> 0 | F20: =(F17/(1-SUM(Configuração!$D$2,Configuração!$D$6)))*Configuração!$D$6 -> 0 | G20: =(G17/(1-SUM(Configuração!$D$2,Configuração!$D$6)))*Configuração!$D$6 -> 0 | H20: =(H17/(1-SUM(Configuração!$D$2,Configuração!$D$6)))*Configuração!$D$6 -> 0 | I20: =(I17/(1-SUM(Configuração!$D$2,Configuração!$D$6)))*Configuração!$D$6 -> 0 | J20: =(J17/(1-SUM(Configuração!$D$2,Configuração!$D$6)))*Configuração!$D$6 -> 0 | K20: =(K17/(1-SUM(Configuração!$D$2,Configuração!$D$6)))*Configuração!$D$6 -> 0 | L20: =(L17/(1-SUM(Configuração!$D$2,Configuração!$D$6)))*Configuração!$D$6 -> 0 | ... AA20: =(AA17/(1-SUM(Configuração!$D$2,Configuração!$D$6)))*Configuração!$D$6 -> 0
B21: TOTAL | C21: =C17+C18 -> 3587480.3 | D21: =SUM(D17:D18) -> 1 | E21: =E17+E18 -> 707536.1 | F21: =F17+F18 -> 1084907.3 | G21: =G17+G18 -> 644869.6 | H21: =H17+H18 -> 124568.08 | I21: =I17+I18 -> 124568.08 | J21: =J17+J18 -> 124568.08 | K21: =K17+K18 -> 124568.08 | L21: =L17+L18 -> 124568.08 | ... AA21: =AA17+AA18 -> 0 | AE21: 3705346.8
B23: Outros Correlatos/Outros Dispêndios | C23: =IFERROR(C16/C10,0) -> 0.16290511
B24: Serviço de Terceiros | C24: =IFERROR(C8/AD21,0) -> 0 | D24: 1 + 4 + 5 | E24: VALOR SYSMAQ | F24: =SERVICO!N10+SERVICO!N14+SERVICO!N15 -> 1600565.4
B25: Dissídio | C25: =Configuração!D4 -> 0.06 | E25: RH SYSMAQ | F25: =SERVICO!P18 -> 315833.7
B26: Inicio do Projeto - Mês/Ano | C26: =Configuração!D3 -> 45597 | E26: TOTAL SYSMAQ | F26: =SUM(F24:F25) -> 1916399.1
B27: Mês de Dissidio 1 | C27: =Configuração!D7 -> 2
B28: Rateio | C28: =Configuração!D13 -> 141 | E28: RHD CONECTHUS | F28: =C6-F25 -> 531981.53
B29: Meses de projeto | C29: =Configuração!D9 -> 12
B30: % RH Indireto | C30: =Configuração!D10 -> 0.2
D31: 1 | E31: VALOR DO PROJETO | F31: =C21-Q21-R21-S21 -> 3558425.7 | G31: 3158389.3
D32: 2 | E32: VALOR + 3 MESES | F32: =Q21+R21+S21 -> 29054.646 | G32: 408714.49
B33: Valor fechado | C33: 0 | E33: VALOR TOTAL (1 + 2) | F33: =SUM(F31:F32) -> 3587480.3 | G33: 3567103.8
B34: Diferença | C34: =C33-AD21 -> 0
D35: Obs: Adicionado o Dispensador
D36: Adicionado a impressora compatível ao dispensador
E38: Valor Anterior SYSMAQ | F38: 1868327.1 | G38: # Diferença
E39: Valor Atual SYSMAQ | F39: =F26 -> 1916399.1 | G39: =F39-F38 -> 48072.002

Sheet Configuração
A1: Rubrica | C1: Parametro | D1: Valor | F1: Tipo de RH
A2: Programas de Computador | C2: Custos Incorridos | D2: 0.2 | F2: Direto
A3: Máquinas e Equipamentos | C3: Inicio Projeto - Mês/Ano | D3: 45597 | F3: Indireto
A4: Implantação, Ampliação ou Modernização | C4: Dissídio | D4: 0.06 | F4: Terceiro
A5: Serviço Técnico de Terceiros | C5: Imposto | D5: 0.05
A6: Material de Consumo | C6: Outros Custos Incorridos | D6: 0
A7: Outros correlatos | C7: Mês Dissidio 1 | D7: 2 | F7: sobre dissídio: Mês deve ser confirmado com o RH. Caso não tenha a confirmação pode ser usado para gerar saldo de rh (mês a definir)
A8: Treinamentos | C8: Mês Dissidio 2 | D8: =D7+12 -> 14
A9: Livros e Periódicos | C9: Meses de Projeto | D9: 12
A10: Viagens | C10: % RH Indireto | D10: 0.2
C11: Vlr Cesta Natalina | D11: 350
C12: Vlr Premiação | D12: 0
C13: Headcount Total | D13: 141
C14: Alocação de Rateio RHD | D14: 1
C15: Alocação de Rateio RHI | D15: 1

Sheet DBFolha
A1: Nome | B1: Cargo | C1: Custo Total | D1: Mês Reajuste | E1: % Reajuste
A2: A Definir - ANALISTA ADMINISTRATIVO | B2: ANALISTA ADMINISTRATIVO | C2: 9501.04 | E2: 0
A3: A definir - ANALISTA DE AUTOMAÇÃO PL | B3: ANALISTA DE AUTOMAÇÃO PL | C3: 15824.93 | E3: 0
A4: A Definir - ANALISTA DE DESENVOLVIMENTO DE EMBALAGEM | B4: ANALISTA DE DESENVOLVIMENTO DE EMBALAGEM | C4: 12370.07 | E4: 0
A5: A Definir - ANALISTA DE ENGENHARIA JR | B5: ANALISTA DE ENGENHARIA JR | C5: 13727.744 | E5: 0
A6: A Definir - ANALISTA DE ENGENHARIA PL | B6: ANALISTA DE ENGENHARIA PL | C6: 14848.8 | E6: 0
A7: A Definir - ANALISTA DE FACILITIES PL | B7: ANALISTA DE FACILITIES PL | C7: 9961.14 | E7: 0
A8: A Definir - ANALISTA DE NECOGIOS JR | B8: ANALISTA DE NEGÓCIOS JR | C8: 11370.22 | E8: 0
A9: A Definir - ANALISTA DE NEGÓCIOS PL | B9: ANALISTA DE NEGÓCIOS PL | C9: 23616.88 | E9: 0
A10: A Definir - ANALISTA DE NEGOCIOS SR | B10: ANALISTA DE NEGOCIOS SR | C10: 17213.231 | E10: 0
A11: A Definir - ANALISTA DE NEGÓCIOS SR | B11: ANALISTA DE NEGÓCIOS SR | C11: 26782.327 | E11: 0
A12: A Definir - ANALISTA DE PD&I JR | B12: ANALISTA DE PD&I JR | C12: 10468.72 | E12: 0
A13: A Definir - ANALISTA DE PD&I SR | B13: ANALISTA DE PD&I SR | C13: 21099.33 | E13: 0
... A231: LIRIAN CORREA DA SILVA | B231: COORDENADOR DE REGULAMENTAÇÃO DE P&D | C231: 16879 | E231: 0

Sheet Equipe
A1: Nome | B1: Cargo | C1: Tipo | D1: Mês | E1: Horas | F1: Alocação | G1: Custo | H1: Justificativa | I1: Vlr R$ | J1: Aloc_ToT | M1: Tot | N1: Tot/12
A2: A Definir - GERENTE DE PROJETOS SR | B2: =IFERROR(VLOOKUP(tbEquipe[[#This Row],[Nome]],tbFOPAG[[Nome]:[Cargo]],2,0),"<Selecionar Nome>") -> GERENTE DE PROJETOS SR | C2: Direto | D2: 1 | E2: =176*tbEquipe[[#This Row],[Alocação]] -> 23.466667 | F2: 0.13333333 | G2: =IFERROR((VLOOKUP(tbEquipe[[#This Row],[Nome]],tbFOPAG[[Nome]:[Custo Total]],3,0)*tbEquipe[[#This Row],[Alocação]]*IF(OR(tbEquipe[[#This Row],[Mês]]>Configuração!$D$7,tbEquipe[[#This Row],[Mês]]=Configuração!$D$7),(1+Configuração!$D$4),1))*IF(OR(tbEquipe[[#This Row],[Mês]]>Configuração!$D$8,tbEquipe[[#This Row],[Mês]]=Configuração!$D$8),(1+Configuração!$D$4),1)+(IF(tbEquipe[[#This Row],[Mês]]=(Configuração!$D$7-1),Configuração!$D$11*tbEquipe[[#This Row],[Alocação]],0))+(IF(tbEquipe[[#This Row],[Mês]]=(Configuração!$D$9),Configuração!$D$12*tbEquipe[[#This Row],[Alocação]],0)),0) -> 5975.6533
A3: A Definir - GERENTE DE PROJETOS SR | B3: =IFERROR(VLOOKUP(tbEquipe[[#This Row],[Nome]],tbFOPAG[[Nome]:[Cargo]],2,0),"<Selecionar Nome>") -> GERENTE DE PROJETOS SR | C3: Direto | D3: 2 | E3: =176*tbEquipe[[#This Row],[Alocação]] -> 23.466667 | F3: 0.13333333 | G3: =IFERROR((VLOOKUP(tbEquipe[[#This Row],[Nome]],tbFOPAG[[Nome]:[Custo Total]],3,0)*tbEquipe[[#This Row],[Alocação]]*IF(OR(tbEquipe[[#This Row],[Mês]]>Configuração!$D$7,tbEquipe[[#This Row],[Mês]]=Configuração!$D$7),(1+Configuração!$D$4),1))*IF(OR(tbEquipe[[#This Row],[Mês]]>Configuração!$D$8,tbEquipe[[#This Row],[Mês]]=Configuração!$D$8),(1+Configuração!$D$4),1)+(IF(tbEquipe[[#This Row],[Mês]]=(Configuração!$D$7-1),Configuração!$D$11*tbEquipe[[#This Row],[Alocação]],0))+(IF(tbEquipe[[#This Row],[Mês]]=(Configuração!$D$9),Configuração!$D$12*tbEquipe[[#This Row],[Alocação]],0)),0) -> 6284.7258
A4: A Definir - GERENTE DE PROJETOS SR | B4: =IFERROR(VLOOKUP(tbEquipe[[#This Row],[Nome]],tbFOPAG[[Nome]:[Cargo]],2,0),"<Selecionar Nome>") -> GERENTE DE PROJETOS SR | C4: Direto | D4: 3 | E4: =176*tbEquipe[[#This Row],[Alocação]] -> 23.466667 | F4: 0.13333333 | G4: =IFERROR((VLOOKUP(tbEquipe[[#This Row],[Nome]],tbFOPAG[[Nome]:[Custo Total]],3,0)*tbEquipe[[#This Row],[Alocação]]*IF(OR(tbEquipe[[#This Row],[Mês]]>Configuração!$D$7,tbEquipe[[#This Row],[Mês]]=Configuração!$D$7),(1+Configuração!$D$4),1))*IF(OR(tbEquipe[[#This Row],[Mês]]>Configuração!$D$8,tbEquipe[[#This Row],[Mês]]=Configuração!$D$8),(1+Configuração!$D$4),1)+(IF(tbEquipe[[#This Row],[Mês]]=(Configuração!$D$7-1),Configuração!$D$11*tbEquipe[[#This Row],[Alocação]],0))+(IF(tbEquipe[[#This Row],[Mês]]=(Configuração!$D$9),Configuração!$D$12*tbEquipe[[#This Row],[Alocação]],0)),0) -> 6284.7258
A5: A Definir - GERENTE DE PROJETOS SR | B5: =IFERROR(VLOOKUP(tbEquipe[[#This Row],[Nome]],tbFOPAG[[Nome]:[Cargo]],2,0),"<Selecionar Nome>") -> GERENTE DE PROJETOS SR | C5: Direto | D5: 4 | E5: =176*tbEquipe[[#This Row],[Alocação]] -> 23.466667 | F5: 0.13333333 | G5: =IFERROR((VLOOKUP(tbEquipe[[#This Row],[Nome]],tbFOPAG[[Nome]:[Custo Total]],3,0)*tbEquipe[[#This Row],[Alocação]]*IF(OR(tbEquipe[[#This Row],[Mês]]>Configuração!$D$7,tbEquipe[[#This Row],[Mês]]=Configuração!$D$7),(1+Configuração!$D$4),1))*IF(OR(tbEquipe[[#This Row],[Mês]]>Configuração!$D$8,tbEquipe[[#This Row],[Mês]]=Configuração!$D$8),(1+Configuração!$D$4),1)+(IF(tbEquipe[[#This Row],[Mês]]=(Configuração!$D$7-1),Configuração!$D$11*tbEquipe[[#This Row],[Alocação]],0))+(IF(tbEquipe[[#This Row],[Mês]]=(Configuração!$D$9),Configuração!$D$12*tbEquipe[[#This Row],[Alocação]],0)),0) -> 6284.7258
A6: A Definir - GERENTE DE PROJETOS SR | B6: =IFERROR(VLOOKUP(tbEquipe[[#This Row],[Nome]],tbFOPAG[[Nome]:[Cargo]],2,0),"<Selecionar Nome>") -> GERENTE DE PROJETOS SR | C6: Direto | D6: 5 | E6: =176*tbEquipe[[#This Row],[Alocação]] -> 23.466667 | F6: 0.13333333 | G6: =IFERROR((VLOOKUP(tbEquipe[[#This Row],[Nome]],tbFOPAG[[Nome]:[Custo Total]],3,0)*tbEquipe[[#This Row],[Alocação]]*IF(OR(tbEquipe[[#This Row],[Mês]]>Configuração!$D$7,tbEquipe[[#This Row],[Mês]]=Configuração!$D$7),(1+Configuração!$D$4),1))*IF(OR(tbEquipe[[#This Row],[Mês]]>Configuração!$D$8,tbEquipe[[#This Row],[Mês]]=Configuração!$D$8),(1+Configuração!$D$4),1)+(IF(tbEquipe[[#This Row],[Mês]]=(Configuração!$D$7-1),Configuração!$D$11*tbEquipe[[#This Row],[Alocação]],0))+(IF(tbEquipe[[#This Row],[Mês]]=(Configuração!$D$9),Configuração!$D$12*tbEquipe[[#This Row],[Alocação]],0)),0) -> 6284.7258
A7: A Definir - GERENTE DE PROJETOS SR | B7: =IFERROR(VLOOKUP(tbEquipe[[#This Row],[Nome]],tbFOPAG[[Nome]:[Cargo]],2,0),"<Selecionar Nome>") -> GERENTE DE PROJETOS SR | C7: Direto | D7: 6 | E7: =176*tbEquipe[[#This Row],[Alocação]] -> 23.466667 | F7: 0.13333333 | G7: =IFERROR((VLOOKUP(tbEquipe[[#This Row],[Nome]],tbFOPAG[[Nome]:[Custo Total]],3,0)*tbEquipe[[#This Row],[Alocação]]*IF(OR(tbEquipe[[#This Row],[Mês]]>Configuração!$D$7,tbEquipe[[#This Row],[Mês]]=Configuração!$D$7),(1+Configuração!$D$4),1))*IF(OR(tbEquipe[[#This Row],[Mês]]>Configuração!$D$8,tbEquipe[[#This Row],[Mês]]=Configuração!$D$8),(1+Configuração!$D$4),1)+(IF(tbEquipe[[#This Row],[Mês]]=(Configuração!$D$7-1),Configuração!$D$11*tbEquipe[[#This Row],[Alocação]],0))+(IF(tbEquipe[[#This Row],[Mês]]=(Configuração!$D$9),Configuração!$D$12*tbEquipe[[#This Row],[Alocação]],0)),0) -> 6284.7258
A8: A Definir - GERENTE DE PROJETOS SR | B8: =IFERROR(VLOOKUP(tbEquipe[[#This Row],[Nome]],tbFOPAG[[Nome]:[Cargo]],2,0),"<Selecionar Nome>") -> GERENTE DE PROJETOS SR | C8: Direto | D8: 7 | E8: =176*tbEquipe[[#This Row],[Alocação]] -> 23.466667 | F8: 0.13333333 | G8: =IFERROR((VLOOKUP(tbEquipe[[#This Row],[Nome]],tbFOPAG[[Nome]:[Custo Total]],3,0)*tbEquipe[[#This Row],[Alocação]]*IF(OR(tbEquipe[[#This Row],[Mês]]>Configuração!$D$7,tbEquipe[[#This Row],[Mês]]=Configuração!$D$7),(1+Configuração!$D$4),1))*IF(OR(tbEquipe[[#This Row],[Mês]]>Configuração!$D$8,tbEquipe[[#This Row],[Mês]]=Configuração!$D$8),(1+Configuração!$D$4),1)+(IF(tbEquipe[[#This Row],[Mês]]=(Configuração!$D$7-1),Configuração!$D$11*tbEquipe[[#This Row],[Alocação]],0))+(IF(tbEquipe[[#This Row],[Mês]]=(Configuração!$D$9),Configuração!$D$12*tbEquipe[[#This Row],[Alocação]],0)),0) -> 6284.7258
A9: A Definir - GERENTE DE PROJETOS SR | B9: =IFERROR(VLOOKUP(tbEquipe[[#This Row],[Nome]],tbFOPAG[[Nome]:[Cargo]],2,0),"<Selecionar Nome>") -> GERENTE DE PROJETOS SR | C9: Direto | D9: 8 | E9: =176*tbEquipe[[#This Row],[Alocação]] -> 23.466667 | F9: 0.13333333 | G9: =IFERROR((VLOOKUP(tbEquipe[[#This Row],[Nome]],tbFOPAG[[Nome]:[Custo Total]],3,0)*tbEquipe[[#This Row],[Alocação]]*IF(OR(tbEquipe[[#This Row],[Mês]]>Configuração!$D$7,tbEquipe[[#This Row],[Mês]]=Configuração!$D$7),(1+Configuração!$D$4),1))*IF(OR(tbEquipe[[#This Row],[Mês]]>Configuração!$D$8,tbEquipe[[#This Row],[Mês]]=Configuração!$D$8),(1+Configuração!$D$4),1)+(IF(tbEquipe[[#This Row],[Mês]]=(Configuração!$D$7-1),Configuração!$D$11*tbEquipe[[#This Row],[Alocação]],0))+(IF(tbEquipe[[#This Row],[Mês]]=(Configuração!$D$9),Configuração!$D$12*tbEquipe[[#This Row],[Alocação]],0)),0) -> 6284.7258 | I9: =SUM(G2:G9) -> 49968.734 | J9: =SUM(F2:F9) -> 1.0666667 | K9: =J9/12 -> 0.088888889 | M9: 1.6 | N9: 0.13333333
A10: A Definir - GERENTE DE PROJETOS SR | B10: =IFERROR(VLOOKUP(tbEquipe[[#This Row],[Nome]],tbFOPAG[[Nome]:[Cargo]],2,0),"<Selecionar Nome>") -> GERENTE DE PROJETOS SR | C10: Direto | D10: 9 | E10: =176*tbEquipe[[#This Row],[Alocação]] -> 23.466667 | F10: 0.13333333 | G10: =IFERROR((VLOOKUP(tbEquipe[[#This Row],[Nome]],tbFOPAG[[Nome]:[Custo Total]],3,0)*tbEquipe[[#This Row],[Alocação]]*IF(OR(tbEquipe[[#This Row],[Mês]]>Configuração!$D$7,tbEquipe[[#This Row],[Mês]]=Configuração!$D$7),(1+Configuração!$D$4),1))*IF(OR(tbEquipe[[#This Row],[Mês]]>Configuração!$D$8,tbEquipe[[#This Row],[Mês]]=Configuração!$D$8),(1+Configuração!$D$4),1)+(IF(tbEquipe[[#This Row],[Mês]]=(Configuração!$D$7-1),Configuração!$D$11*tbEquipe[[#This Row],[Alocação]],0))+(IF(tbEquipe[[#This Row],[Mês]]=(Configuração!$D$9),Configuração!$D$12*tbEquipe[[#This Row],[Alocação]],0)),0) -> 6284.7258
A11: A Definir - GERENTE DE PROJETOS SR | B11: =IFERROR(VLOOKUP(tbEquipe[[#This Row],[Nome]],tbFOPAG[[Nome]:[Cargo]],2,0),"<Selecionar Nome>") -> GERENTE DE PROJETOS SR | C11: Direto | D11: 10 | E11: =176*tbEquipe[[#This Row],[Alocação]] -> 23.466667 | F11: 0.13333333 | G11: =IFERROR((VLOOKUP(tbEquipe[[#This Row],[Nome]],tbFOPAG[[Nome]:[Custo Total]],3,0)*tbEquipe[[#This Row],[Alocação]]*IF(OR(tbEquipe[[#This Row],[Mês]]>Configuração!$D$7,tbEquipe[[#This Row],[Mês]]=Configuração!$D$7),(1+Configuração!$D$4),1))*IF(OR(tbEquipe[[#This Row],[Mês]]>Configuração!$D$8,tbEquipe[[#This Row],[Mês]]=Configuração!$D$8),(1+Configuração!$D$4),1)+(IF(tbEquipe[[#This Row],[Mês]]=(Configuração!$D$7-1),Configuração!$D$11*tbEquipe[[#This Row],[Alocação]],0))+(IF(tbEquipe[[#This Row],[Mês]]=(Configuração!$D$9),Configuração!$D$12*tbEquipe[[#This Row],[Alocação]],0)),0) -> 6284.7258
A12: A Definir - GERENTE DE PROJETOS SR | B12: =IFERROR(VLOOKUP(tbEquipe[[#This Row],[Nome]],tbFOPAG[[Nome]:[Cargo]],2,0),"<Selecionar Nome>") -> GERENTE DE PROJETOS SR | C12: Direto | D12: 11 | E12: =176*tbEquipe[[#This Row],[Alocação]] -> 23.466667 | F12: 0.13333333 | G12: =IFERROR((VLOOKUP(tbEquipe[[#This Row],[Nome]],tbFOPAG[[Nome]:[Custo Total]],3,0)*tbEquipe[[#This Row],[Alocação]]*IF(OR(tbEquipe[[#This Row],[Mês]]>Configuração!$D$7,tbEquipe[[#This Row],[Mês]]=Configuração!$D$7),(1+Configuração!$D$4),1))*IF(OR(tbEquipe[[#This Row],[Mês]]>Configuração!$D$8,tbEquipe[[#This Row],[Mês]]=Configuração!$D$8),(1+Configuração!$D$4),1)+(IF(tbEquipe[[#This Row],[Mês]]=(Configuração!$D$7-1),Configuração!$D$11*tbEquipe[[#This Row],[Alocação]],0))+(IF(tbEquipe[[#This Row],[Mês]]=(Configuração!$D$9),Configuração!$D$12*tbEquipe[[#This Row],[Alocação]],0)),0) -> 6284.7258
A13: A Definir - GERENTE DE PROJETOS SR | B13: =IFERROR(VLOOKUP(tbEquipe[[#This Row],[Nome]],tbFOPAG[[Nome]:[Cargo]],2,0),"<Selecionar Nome>") -> GERENTE DE PROJETOS SR | C13: Direto | D13: 12 | E13: =176*tbEquipe[[#This Row],[Alocação]] -> 23.466667 | F13: 0.13333333 | G13: =IFERROR((VLOOKUP(tbEquipe[[#This Row],[Nome]],tbFOPAG[[Nome]:[Custo Total]],3,0)*tbEquipe[[#This Row],[Alocação]]*IF(OR(tbEquipe[[#This Row],[Mês]]>Configuração!$D$7,tbEquipe[[#This Row],[Mês]]=Configuração!$D$7),(1+Configuração!$D$4),1))*IF(OR(tbEquipe[[#This Row],[Mês]]>Configuração!$D$8,tbEquipe[[#This Row],[Mês]]=Configuração!$D$8),(1+Configuração!$D$4),1)+(IF(tbEquipe[[#This Row],[Mês]]=(Configuração!$D$7-1),Configuração!$D$11*tbEquipe[[#This Row],[Alocação]],0))+(IF(tbEquipe[[#This Row],[Mês]]=(Configuração!$D$9),Configuração!$D$12*tbEquipe[[#This Row],[Alocação]],0)),0) -> 6284.7258
A14: A Definir - GERENTE DE PROJETOS SR | B14: =IFERROR(VLOOKUP(tbEquipe[[#This Row],[Nome]],tbFOPAG[[Nome]:[Cargo]],2,0),"<Selecionar Nome>") -> GERENTE DE PROJETOS SR | C14: Direto | D14: 13 | E14: =176*tbEquipe[[#This Row],[Alocação]] -> 8.8 | F14: 0.05 | G14: =IFERROR((VLOOKUP(tbEquipe[[#This Row],[Nome]],tbFOPAG[[Nome]:[Custo Total]],3,0)*tbEquipe[[#This Row],[Alocação]]*IF(OR(tbEquipe[[#This Row],[Mês]]>Configuração!$D$7,tbEquipe[[#This Row],[Mês]]=Configuração!$D$7),(1+Configuração!$D$4),1))*IF(OR(tbEquipe[[#This Row],[Mês]]>Configuração!$D$8,tbEquipe[[#This Row],[Mês]]=Configuração!$D$8),(1+Configuração!$D$4),1)+(IF(tbEquipe[[#This Row],[Mês]]=(Configuração!$D$7-1),Configuração!$D$11*tbEquipe[[#This Row],[Alocação]],0))+(IF(tbEquipe[[#This Row],[Mês]]=(Configuração!$D$9),Configuração!$D$12*tbEquipe[[#This Row],[Alocação]],0)),0) -> 2356.7722
A15: A Definir - GERENTE DE PROJETOS SR | B15: =IFERROR(VLOOKUP(tbEquipe[[#This Row],[Nome]],tbFOPAG[[Nome]:[Cargo]],2,0),"<Selecionar Nome>") -> GERENTE DE PROJETOS SR | C15: Direto | D15: 14 | E15: =176*tbEquipe[[#This Row],[Alocação]] -> 8.8 | F15: 0.05 | G15: =IFERROR((VLOOKUP(tbEquipe[[#This Row],[Nome]],tbFOPAG[[Nome]:[Custo Total]],3,0)*tbEquipe[[#This Row],[Alocação]]*IF(OR(tbEquipe[[#This Row],[Mês]]>Configuração!$D$7,tbEquipe[[#This Row],[Mês]]=Configuração!$D$7),(1+Configuração!$D$4),1))*IF(OR(tbEquipe[[#This Row],[Mês]]>Configuração!$D$8,tbEquipe[[#This Row],[Mês]]=Configuração!$D$8),(1+Configuração!$D$4),1)+(IF(tbEquipe[[#This Row],[Mês]]=(Configuração!$D$7-1),Configuração!$D$11*tbEquipe[[#This Row],[Alocação]],0))+(IF(tbEquipe[[#This Row],[Mês]]=(Configuração!$D$9),Configuração!$D$12*tbEquipe[[#This Row],[Alocação]],0)),0) -> 2498.1785
A16: A Definir - GERENTE DE PROJETOS SR | B16: =IFERROR(VLOOKUP(tbEquipe[[#This Row],[Nome]],tbFOPAG[[Nome]:[Cargo]],2,0),"<Selecionar Nome>") -> GERENTE DE PROJETOS SR | C16: Direto | D16: 15 | E16: =176*tbEquipe[[#This Row],[Alocação]] -> 8.8 | F16: 0.05 | G16: =IFERROR((VLOOKUP(tbEquipe[[#This Row],[Nome]],tbFOPAG[[Nome]:[Custo Total]],3,0)*tbEquipe[[#This Row],[Alocação]]*IF(OR(tbEquipe[[#This Row],[Mês]]>Configuração!$D$7,tbEquipe[[#This Row],[Mês]]=Configuração!$D$7),(1+Configuração!$D$4),1))*IF(OR(tbEquipe[[#This Row],[Mês]]>Configuração!$D$8,tbEquipe[[#This Row],[Mês]]=Configuração!$D$8),(1+Configuração!$D$4),1)+(IF(tbEquipe[[#This Row],[Mês]]=(Configuração!$D$7-1),Configuração!$D$11*tbEquipe[[#This Row],[Alocação]],0))+(IF(tbEquipe[[#This Row],[Mês]]=(Configuração!$D$9),Configuração!$D$12*tbEquipe[[#This Row],[Alocação]],0)),0) -> 2498.1785 | I16: =SUM(G2:G16) -> 82460.767
A17: A Definir - LÍDER DE PROJETOS | B17: =IFERROR(VLOOKUP(tbEquipe[[#This Row],[Nome]],tbFOPAG[[Nome]:[Cargo]],2,0),"<Selecionar Nome>") -> LÍDER DE PROJETOS | C17: Direto | D17: 1 | E17: =176*tbEquipe[[#This Row],[Alocação]] -> 23.466667 | F17: 0.13333333 | G17: =IFERROR((VLOOKUP(tbEquipe[[#This Row],[Nome]],tbFOPAG[[Nome]:[Custo Total]],3,0)*tbEquipe[[#This Row],[Alocação]]*IF(OR(tbEquipe[[#This Row],[Mês]]>Configuração!$D$7,tbEquipe[[#This Row],[Mês]]=Configuração!$D$7),(1+Configuração!$D$4),1))*IF(OR(tbEquipe[[#This Row],[Mês]]>Configuração!$D$8,tbEquipe[[#This Row],[Mês]]=Configuração!$D$8),(1+Configuração!$D$4),1)+(IF(tbEquipe[[#This Row],[Mês]]=(Configuração!$D$7-1),Configuração!$D$11*tbEquipe[[#This Row],[Alocação]],0))+(IF(tbEquipe[[#This Row],[Mês]]=(Configuração!$D$9),Configuração!$D$12*tbEquipe[[#This Row],[Alocação]],0)),0) -> 3175.427
A18: A Definir - LÍDER DE PROJETOS | B18: =IFERROR(VLOOKUP(tbEquipe[[#This Row],[Nome]],tbFOPAG[[Nome]:[Cargo]],2,0),"<Selecionar Nome>") -> LÍDER DE PROJETOS | C18: Direto | D18: 2 | E18: =176*tbEquipe[[#This Row],[Alocação]] -> 23.466667 | F18: 0.13333333 | G18: =IFERROR((VLOOKUP(tbEquipe[[#This Row],[Nome]],tbFOPAG[[Nome]:[Custo Total]],3,0)*tbEquipe[[#This Row],[Alocação]]*IF(OR(tbEquipe[[#This Row],[Mês]]>Configuração!$D$7,tbEquipe[[#This Row],[Mês]]=Configuração!$D$7),(1+Configuração!$D$4),1))*IF(OR(tbEquipe[[#This Row],[Mês]]>Configuração!$D$8,tbEquipe[[#This Row],[Mês]]=Configuração!$D$8),(1+Configuração!$D$4),1)+(IF(tbEquipe[[#This Row],[Mês]]=(Configuração!$D$7-1),Configuração!$D$11*tbEquipe[[#This Row],[Alocação]],0))+(IF(tbEquipe[[#This Row],[Mês]]=(Configuração!$D$9),Configuração!$D$12*tbEquipe[[#This Row],[Alocação]],0)),0) -> 3316.4859
A19: A Definir - LÍDER DE PROJETOS | B19: =IFERROR(VLOOKUP(tbEquipe[[#This Row],[Nome]],tbFOPAG[[Nome]:[Cargo]],2,0),"<Selecionar Nome>") -> LÍDER DE PROJETOS | C19: Direto | D19: 3 | E19: =176*tbEquipe[[#This Row],[Alocação]] -> 23.466667 | F19: 0.13333333 | G19: =IFERROR((VLOOKUP(tbEquipe[[#This Row],[Nome]],tbFOPAG[[Nome]:[Custo Total]],3,0)*tbEquipe[[#This Row],[Alocação]]*IF(OR(tbEquipe[[#This Row],[Mês]]>Configuração!$D$7,tbEquipe[[#This Row],[Mês]]=Configuração!$D$7),(1+Configuração!$D$4),1))*IF(OR(tbEquipe[[#This Row],[Mês]]>Configuração!$D$8,tbEquipe[[#This Row],[Mês]]=Configuração!$D$8),(1+Configuração!$D$4),1)+(IF(tbEquipe[[#This Row],[Mês]]=(Configuração!$D$7-1),Configuração!$D$11*tbEquipe[[#This Row],[Alocação]],0))+(IF(tbEquipe[[#This Row],[Mês]]=(Configuração!$D$9),Configuração!$D$12*tbEquipe[[#This Row],[Alocação]],0)),0) -> 3316.4859
A20: A Definir - LÍDER DE PROJETOS | B20: =IFERROR(VLOOKUP(tbEquipe[[#This Row],[Nome]],tbFOPAG[[Nome]:[Cargo]],2,0),"<Selecionar Nome>") -> LÍDER DE PROJETOS | C20: Direto | D20: 4 | E20: =176*tbEquipe[[#This Row],[Alocação]] -> 23.466667 | F20: 0.13333333 | G20: =IFERROR((VLOOKUP(tbEquipe[[#This Row],[Nome]],tbFOPAG[[Nome]:[Custo Total]],3,0)*tbEquipe[[#This Row],[Alocação]]*IF(OR(tbEquipe[[#This Row],[Mês]]>Configuração!$D$7,tbEquipe[[#This Row],[Mês]]=Configuração!$D$7),(1+Configuração!$D$4),1))*IF(OR(tbEquipe[[#This Row],[Mês]]>Configuração!$D$8,tbEquipe[[#This Row],[Mês]]=Configuração!$D$8),(1+Configuração!$D$4),1)+(IF(tbEquipe[[#This Row],[Mês]]=(Configuração!$D$7-1),Configuração!$D$11*tbEquipe[[#This Row],[Alocação]],0))+(IF(tbEquipe[[#This Row],[Mês]]=(Configuração!$D$9),Configuração!$D$12*tbEquipe[[#This Row],[Alocação]],0)),0) -> 3316.4859
A21: A Definir - LÍDER DE PROJETOS | B21: =IFERROR(VLOOKUP(tbEquipe[[#This Row],[Nome]],tbFOPAG[[Nome]:[Cargo]],2,0),"<Selecionar Nome>") -> LÍDER DE PROJETOS | C21: Direto | D21: 5 | E21: =176*tbEquipe[[#This Row],[Alocação]] -> 23.466667 | F21: 0.13333333 | G21: =IFERROR((VLOOKUP(tbEquipe[[#This Row],[Nome]],tbFOPAG[[Nome]:[Custo Total]],3,0)*tbEquipe[[#This Row],[Alocação]]*IF(OR(tbEquipe[[#This Row],[Mês]]>Configuração!$D$7,tbEquipe[[#This Row],[Mês]]=Configuração!$D$7),(1+Configuração!$D$4),1))*IF(OR(tbEquipe[[#This Row],[Mês]]>Configuração!$D$8,tbEquipe[[#This Row],[Mês]]=Configuração!$D$8),(1+Configuração!$D$4),1)+(IF(tbEquipe[[#This Row],[Mês]]=(Configuração!$D$7-1),Configuração!$D$11*tbEquipe[[#This Row],[Alocação]],0))+(IF(tbEquipe[[#This Row],[Mês]]=(Configuração!$D$9),Configuração!$D$12*tbEquipe[[#This Row],[Alocação]],0)),0) -> 3316.4859
A22: A Definir - LÍDER DE PROJETOS | B22: =IFERROR(VLOOKUP(tbEquipe[[#This Row],[Nome]],tbFOPAG[[Nome]:[Cargo]],2,0),"<Selecionar Nome>") -> LÍDER DE PROJETOS | C22: Direto | D22: 6 | E22: =176*tbEquipe[[#This Row],[Alocação]] -> 23.466667 | F22: 0.13333333 | G22: =IFERROR((VLOOKUP(tbEquipe[[#This Row],[Nome]],tbFOPAG[[Nome]:[Custo Total]],3,0)*tbEquipe[[#This Row],[Alocação]]*IF(OR(tbEquipe[[#This Row],[Mês]]>Configuração!$D$7,tbEquipe[[#This Row],[Mês]]=Configuração!$D$7),(1+Configuração!$D$4),1))*IF(OR(tbEquipe[[#This Row],[Mês]]>Configuração!$D$8,tbEquipe[[#This Row],[Mês]]=Configuração!$D$8),(1+Configuração!$D$4),1)+(IF(tbEquipe[[#This Row],[Mês]]=(Configuração!$D$7-1),Configuração!$D$11*tbEquipe[[#This Row],[Alocação]],0))+(IF(tbEquipe[[#This Row],[Mês]]=(Configuração!$D$9),Configuração!$D$12*tbEquipe[[#This Row],[Alocação]],0)),0) -> 3316.4859
A23: A Definir - LÍDER DE PROJETOS | B23: =IFERROR(VLOOKUP(tbEquipe[[#This Row],[Nome]],tbFOPAG[[Nome]:[Cargo]],2,0),"<Selecionar Nome>") -> LÍDER DE PROJETOS | C23: Direto | D23: 7 | E23: =176*tbEquipe[[#This Row],[Alocação]] -> 23.466667 | F23: 0.13333333 | G23: =IFERROR((VLOOKUP(tbEquipe[[#This Row],[Nome]],tbFOPAG[[Nome]:[Custo Total]],3,0)*tbEquipe[[#This Row],[Alocação]]*IF(OR(tbEquipe[[#This Row],[Mês]]>Configuração!$D$7,tbEquipe[[#This Row],[Mês]]=Configuração!$D$7),(1+Configuração!$D$4),1))*IF(OR(tbEquipe[[#This Row],[Mês]]>Configuração!$D$8,tbEquipe[[#This Row],[Mês]]=Configuração!$D$8),(1+Configuração!$D$4),1)+(IF(tbEquipe[[#This Row],[Mês]]=(Configuração!$D$7-1),Configuração!$D$11*tbEquipe[[#This Row],[Alocação]],0))+(IF(tbEquipe[[#This Row],[Mês]]=(Configuração!$D$9),Configuração!$D$12*tbEquipe[[#This Row],[Alocação]],0)),0) -> 3316.4859
A24: A Definir - LÍDER DE PROJETOS | B24: =IFERROR(VLOOKUP(tbEquipe[[#This Row],[Nome]],tbFOPAG[[Nome]:[Cargo]],2,0),"<Selecionar Nome>") -> LÍDER DE PROJETOS | C24: Direto | D24: 8 | E24: =176*tbEquipe[[#This Row],[Alocação]] -> 23.466667 | F24: 0.13333333 | G24: =IFERROR((VLOOKUP(tbEquipe[[#This Row],[Nome]],tbFOPAG[[Nome]:[Custo Total]],3,0)*tbEquipe[[#This Row],[Alocação]]*IF(OR(tbEquipe[[#This Row],[Mês]]>Configuração!$D$7,tbEquipe[[#This Row],[Mês]]=Configuração!$D$7),(1+Configuração!$D$4),1))*IF(OR(tbEquipe[[#This Row],[Mês]]>Configuração!$D$8,tbEquipe[[#This Row],[Mês]]=Configuração!$D$8),(1+Configuração!$D$4),1)+(IF(tbEquipe[[#This Row],[Mês]]=(Configuração!$D$7-1),Configuração!$D$11*tbEquipe[[#This Row],[Alocação]],0))+(IF(tbEquipe[[#This Row],[Mês]]=(Configuração!$D$9),Configuração!$D$12*tbEquipe[[#This Row],[Alocação]],0)),0) -> 3316.4859 | I24: =SUM(G17:G24) -> 26390.829 | J24: =SUM(F17:F24) -> 1.0666667 | K24: =J24/12 -> 0.088888889 | M24: 1.6 | N24: 0.13333333
A25: A Definir - LÍDER DE PROJETOS | B25: =IFERROR(VLOOKUP(tbEquipe[[#This Row],[Nome]],tbFOPAG[[Nome]:[Cargo]],2,0),"<Selecionar Nome>") -> LÍDER DE PROJETOS | C25: Direto | D25: 9 | E25: =176*tbEquipe[[#This Row],[Alocação]] -> 23.466667 | F25: 0.13333333 | G25: =IFERROR((VLOOKUP(tbEquipe[[#This Row],[Nome]],tbFOPAG[[Nome]:[Custo Total]],3,0)*tbEquipe[[#This Row],[Alocação]]*IF(OR(tbEquipe[[#This Row],[Mês]]>Configuração!$D$7,tbEquipe[[#This Row],[Mês]]=Configuração!$D$7),(1+Configuração!$D$4),1))*IF(OR(tbEquipe[[#This Row],[Mês]]>Configuração!$D$8,tbEquipe[[#This Row],[Mês]]=Configuração!$D$8),(1+Configuração!$D$4),1)+(IF(tbEquipe[[#This Row],[Mês]]=(Configuração!$D$7-1),Configuração!$D$11*tbEquipe[[#This Row],[Alocação]],0))+(IF(tbEquipe[[#This Row],[Mês]]=(Configuração!$D$9),Configuração!$D$12*tbEquipe[[#This Row],[Alocação]],0)),0) -> 3316.4859
A26: A Definir - LÍDER DE PROJETOS | B26: =IFERROR(VLOOKUP(tbEquipe[[#This Row],[Nome]],tbFOPAG[[Nome]:[Cargo]],2,0),"<Selecionar Nome>") -> LÍDER DE PROJETOS | C26: Direto | D26: 10 | E26: =176*tbEquipe[[#This Row],[Alocação]] -> 23.466667 | F26: 0.13333333 | G26: =IFERROR((VLOOKUP(tbEquipe[[#This Row],[Nome]],tbFOPAG[[Nome]:[Custo Total]],3,0)*tbEquipe[[#This Row],[Alocação]]*IF(OR(tbEquipe[[#This Row],[Mês]]>Configuração!$D$7,tbEquipe[[#This Row],[Mês]]=Configuração!$D$7),(1+Configuração!$D$4),1))*IF(OR(tbEquipe[[#This Row],[Mês]]>Configuração!$D$8,tbEquipe[[#This Row],[Mês]]=Configuração!$D$8),(1+Configuração!$D$4),1)+(IF(tbEquipe[[#This Row],[Mês]]=(Configuração!$D$7-1),Configuração!$D$11*tbEquipe[[#This Row],[Alocação]],0))+(IF(tbEquipe[[#This Row],[Mês]]=(Configuração!$D$9),Configuração!$D$12*tbEquipe[[#This Row],[Alocação]],0)),0) -> 3316.4859
A27: A Definir - LÍDER DE PROJETOS | B27: =IFERROR(VLOOKUP(tbEquipe[[#This Row],[Nome]],tbFOPAG[[Nome]:[Cargo]],2,0),"<Selecionar Nome>") -> LÍDER DE PROJETOS | C27: Direto | D27: 11 | E27: =176*tbEquipe[[#This Row],[Alocação]] -> 23.466667 | F27: 0.13333333 | G27: =IFERROR((VLOOKUP(tbEquipe[[#This Row],[Nome]],tbFOPAG[[Nome]:[Custo Total]],3,0)*tbEquipe[[#This Row],[Alocação]]*IF(OR(tbEquipe[[#This Row],[Mês]]>Configuração!$D$7,tbEquipe[[#This Row],[Mês]]=Configuração!$D$7),(1+Configuração!$D$4),1))*IF(OR(tbEquipe[[#This Row],[Mês]]>Configuração!$D$8,tbEquipe[[#This Row],[Mês]]=Configuração!$D$8),(1+Configuração!$D$4),1)+(IF(tbEquipe[[#This Row],[Mês]]=(Configuração!$D$7-1),Configuração!$D$11*tbEquipe[[#This Row],[Alocação]],0))+(IF(tbEquipe[[#This Row],[Mês]]=(Configuração!$D$9),Configuração!$D$12*tbEquipe[[#This Row],[Alocação]],0)),0) -> 3316.4859
A28: A Definir - LÍDER DE PROJETOS | B28: =IFERROR(VLOOKUP(tbEquipe[[#This Row],[Nome]],tbFOPAG[[Nome]:[Cargo]],2,0),"<Selecionar Nome>") -> LÍDER DE PROJETOS | C28: Direto | D28: 12 | E28: =176*tbEquipe[[#This Row],[Alocação]] -> 23.466667 | F28: 0.13333333 | G28: =IFERROR((VLOOKUP(tbEquipe[[#This Row],[Nome]],tbFOPAG[[Nome]:[Custo Total]],3,0)*tbEquipe[[#This Row],[Alocação]]*IF(OR(tbEquipe[[#This Row],[Mês]]>Configuração!$D$7,tbEquipe[[#This Row],[Mês]]=Configuração!$D$7),(1+Configuração!$D$4),1))*IF(OR(tbEquipe[[#This Row],[Mês]]>Configuração!$D$8,tbEquipe[[#This Row],[Mês]]=Configuração!$D$8),(1+Configuração!$D$4),1)+(IF(tbEquipe[[#This Row],[Mês]]=(Configuração!$D$7-1),Configuração!$D$11*tbEquipe[[#This Row],[Alocação]],0))+(IF(tbEquipe[[#This Row],[Mês]]=(Configuração!$D$9),Configuração!$D$12*tbEquipe[[#This Row],[Alocação]],0)),0) -> 3316.4859
A29: A Definir - LÍDER DE PROJETOS | B29: =IFERROR(VLOOKUP(tbEquipe[[#This Row],[Nome]],tbFOPAG[[Nome]:[Cargo]],2,0),"<Selecionar Nome>") -> LÍDER DE PROJETOS | C29: Direto | D29: 13 | E29: =176*tbEquipe[[#This Row],[Alocação]] -> 8.8 | F29: 0.05 | G29: =IFERROR((VLOOKUP(tbEquipe[[#This Row],[Nome]],tbFOPAG[[Nome]:[Custo Total]],3,0)*tbEquipe[[#This Row],[Alocação]]*IF(OR(tbEquipe[[#This Row],[Mês]]>Configuração!$D$7,tbEquipe[[#This Row],[Mês]]=Configuração!$D$7),(1+Configuração!$D$4),1))*IF(OR(tbEquipe[[#This Row],[Mês]]>Configuração!$D$8,tbEquipe[[#This Row],[Mês]]=Configuração!$D$8),(1+Configuração!$D$4),1)+(IF(tbEquipe[[#This Row],[Mês]]=(Configuração!$D$7-1),Configuração!$D$11*tbEquipe[[#This Row],[Alocação]],0))+(IF(tbEquipe[[#This Row],[Mês]]=(Configuração!$D$9),Configuração!$D$12*tbEquipe[[#This Row],[Alocação]],0)),0) -> 1243.6822
A30: A Definir - LÍDER DE PROJETOS | B30: =IFERROR(VLOOKUP(tbEquipe[[#This Row],[Nome]],tbFOPAG[[Nome]:[Cargo]],2,0),"<Selecionar Nome>") -> LÍDER DE PROJETOS | C30: Direto | D30: 14 | E30: =176*tbEquipe[[#This Row],[Alocação]] -> 8.8 | F30: 0.05 | G30: =IFERROR((VLOOKUP(tbEquipe[[#This Row],[Nome]],tbFOPAG[[Nome]:[Custo Total]],3,0)*tbEquipe[[#This Row],[Alocação]]*IF(OR(tbEquipe[[#This Row],[Mês]]>Configuração!$D$7,tbEquipe[[#This Row],[Mês]]=Configuração!$D$7),(1+Configuração!$D$4),1))*IF(OR(tbEquipe[[#This Row],[Mês]]>Configuração!$D$8,tbEquipe[[#This Row],[Mês]]=Configuração!$D$8),(1+Configuração!$D$4),1)+(IF(tbEquipe[[#This Row],[Mês]]=(Configuração!$D$7-1),Configuração!$D$11*tbEquipe[[#This Row],[Alocação]],0))+(IF(tbEquipe[[#This Row],[Mês]]=(Configuração!$D$9),Configuração!$D$12*tbEquipe[[#This Row],[Alocação]],0)),0) -> 1318.3032
A31: A Definir - LÍDER DE PROJETOS | B31: =IFERROR(VLOOKUP(tbEquipe[[#This Row],[Nome]],tbFOPAG[[Nome]:[Cargo]],2,0),"<Selecionar Nome>") -> LÍDER DE PROJETOS | C31: Direto | D31: 15 | E31: =176*tbEquipe[[#This Row],[Alocação]] -> 8.8 | F31: 0.05 | G31: =IFERROR((VLOOKUP(tbEquipe[[#This Row],[Nome]],tbFOPAG[[Nome]:[Custo Total]],3,0)*tbEquipe[[#This Row],[Alocação]]*IF(OR(tbEquipe[[#This Row],[Mês]]>Configuração!$D$7,tbEquipe[[#This Row],[Mês]]=Configuração!$D$7),(1+Configuração!$D$4),1))*IF(OR(tbEquipe[[#This Row],[Mês]]>Configuração!$D$8,tbEquipe[[#This Row],[Mês]]=Configuração!$D$8),(1+Configuração!$D$4),1)+(IF(tbEquipe[[#This Row],[Mês]]=(Configuração!$D$7-1),Configuração!$D$11*tbEquipe[[#This Row],[Alocação]],0))+(IF(tbEquipe[[#This Row],[Mês]]=(Configuração!$D$9),Configuração!$D$12*tbEquipe[[#This Row],[Alocação]],0)),0) -> 1318.3032 | I31: =SUM(G17:G31) -> 43537.061
A32: A Definir - ANALISTA DE NEGOCIOS SR | B32: =IFERROR(VLOOKUP(tbEquipe[[#This Row],[Nome]],tbFOPAG[[Nome]:[Cargo]],2,0),"<Selecionar Nome>") -> ANALISTA DE NEGOCIOS SR | C32: Direto | D32: 1 | E32: =176*tbEquipe[[#This Row],[Alocação]] -> 38.72 | F32: 0.22 | G32: =IFERROR((VLOOKUP(tbEquipe[[#This Row],[Nome]],tbFOPAG[[Nome]:[Custo Total]],3,0)*tbEquipe[[#This Row],[Alocação]]*IF(OR(tbEquipe[[#This Row],[Mês]]>Configuração!$D$7,tbEquipe[[#This Row],[Mês]]=Configuração!$D$7),(1+Configuração!$D$4),1))*IF(OR(tbEquipe[[#This Row],[Mês]]>Configuração!$D$8,tbEquipe[[#This Row],[Mês]]=Configuração!$D$8),(1+Configuração!$D$4),1)+(IF(tbEquipe[[#This Row],[Mês]]=(Configuração!$D$7-1),Configuração!$D$11*tbEquipe[[#This Row],[Alocação]],0))+(IF(tbEquipe[[#This Row],[Mês]]=(Configuração!$D$9),Configuração!$D$12*tbEquipe[[#This Row],[Alocação]],0)),0) -> 3863.9108
A33: A Definir - ANALISTA DE NEGOCIOS SR | B33: =IFERROR(VLOOKUP(tbEquipe[[#This Row],[Nome]],tbFOPAG[[Nome]:[Cargo]],2,0),"<Selecionar Nome>") -> ANALISTA DE NEGOCIOS SR | C33: Direto | D33: 2 | E33: =176*tbEquipe[[#This Row],[Alocação]] -> 38.72 | F33: 0.22 | G33: =IFERROR((VLOOKUP(tbEquipe[[#This Row],[Nome]],tbFOPAG[[Nome]:[Custo Total]],3,0)*tbEquipe[[#This Row],[Alocação]]*IF(OR(tbEquipe[[#This Row],[Mês]]>Configuração!$D$7,tbEquipe[[#This Row],[Mês]]=Configuração!$D$7),(1+Configuração!$D$4),1))*IF(OR(tbEquipe[[#This Row],[Mês]]>Configuração!$D$8,tbEquipe[[#This Row],[Mês]]=Configuração!$D$8),(1+Configuração!$D$4),1)+(IF(tbEquipe[[#This Row],[Mês]]=(Configuração!$D$7-1),Configuração!$D$11*tbEquipe[[#This Row],[Alocação]],0))+(IF(tbEquipe[[#This Row],[Mês]]=(Configuração!$D$9),Configuração!$D$12*tbEquipe[[#This Row],[Alocação]],0)),0) -> 4014.1254
A34: A Definir - ANALISTA DE NEGOCIOS SR | B34: =IFERROR(VLOOKUP(tbEquipe[[#This Row],[Nome]],tbFOPAG[[Nome]:[Cargo]],2,0),"<Selecionar Nome>") -> ANALISTA DE NEGOCIOS SR | C34: Direto | D34: 3 | E34: =176*tbEquipe[[#This Row],[Alocação]] -> 38.72 | F34: 0.22 | G34: =IFERROR((VLOOKUP(tbEquipe[[#This Row],[Nome]],tbFOPAG[[Nome]:[Custo Total]],3,0)*tbEquipe[[#This Row],[Alocação]]*IF(OR(tbEquipe[[#This Row],[Mês]]>Configuração!$D$7,tbEquipe[[#This Row],[Mês]]=Configuração!$D$7),(1+Configuração!$D$4),1))*IF(OR(tbEquipe[[#This Row],[Mês]]>Configuração!$D$8,tbEquipe[[#This Row],[Mês]]=Configuração!$D$8),(1+Configuração!$D$4),1)+(IF(tbEquipe[[#This Row],[Mês]]=(Configuração!$D$7-1),Configuração!$D$11*tbEquipe[[#This Row],[Alocação]],0))+(IF(tbEquipe[[#This Row],[Mês]]=(Configuração!$D$9),Configuração!$D$12*tbEquipe[[#This Row],[Alocação]],0)),0) -> 4014.1254
A35: A Definir - ANALISTA DE NEGOCIOS SR | B35: =IFERROR(VLOOKUP(tbEquipe[[#This Row],[Nome]],tbFOPAG[[Nome]:[Cargo]],2,0),"<Selecionar Nome>") -> ANALISTA DE NEGOCIOS SR | C35: Direto | D35: 4 | E35: =176*tbEquipe[[#This Row],[Alocação]] -> 38.72 | F35: 0.22 | G35: =IFERROR((VLOOKUP(tbEquipe[[#This Row],[Nome]],tbFOPAG[[Nome]:[Custo Total]],3,0)*tbEquipe[[#This Row],[Alocação]]*IF(OR(tbEquipe[[#This Row],[Mês]]>Configuração!$D$7,tbEquipe[[#This Row],[Mês]]=Configuração!$D$7),(1+Configuração!$D$4),1))*IF(OR(tbEquipe[[#This Row],[Mês]]>Configuração!$D$8,tbEquipe[[#This Row],[Mês]]=Configuração!$D$8),(1+Configuração!$D$4),1)+(IF(tbEquipe[[#This Row],[Mês]]=(Configuração!$D$7-1),Configuração!$D$11*tbEquipe[[#This Row],[Alocação]],0))+(IF(tbEquipe[[#This Row],[Mês]]=(Configuração!$D$9),Configuração!$D$12*tbEquipe[[#This Row],[Alocação]],0)),0) -> 4014.1254
A36: A Definir - ANALISTA DE NEGOCIOS SR | B36: =IFERROR(VLOOKUP(tbEquipe[[#This Row],[Nome]],tbFOPAG[[Nome]:[Cargo]],2,0),"<Selecionar Nome>") -> ANALISTA DE NEGOCIOS SR | C36: Direto | D36: 5 | E36: =176*tbEquipe[[#This Row],[Alocação]] -> 38.72 | F36: 0.22 | G36: =IFERROR((VLOOKUP(tbEquipe[[#This Row],[Nome]],tbFOPAG[[Nome]:[Custo Total]],3,0)*tbEquipe[[#This Row],[Alocação]]*IF(OR(tbEquipe[[#This Row],[Mês]]>Configuração!$D$7,tbEquipe[[#This Row],[Mês]]=Configuração!$D$7),(1+Configuração!$D$4),1))*IF(OR(tbEquipe[[#This Row],[Mês]]>Configuração!$D$8,tbEquipe[[#This Row],[Mês]]=Configuração!$D$8),(1+Configuração!$D$4),1)+(IF(tbEquipe[[#This Row],[Mês]]=(Configuração!$D$7-1),Configuração!$D$11*tbEquipe[[#This Row],[Alocação]],0))+(IF(tbEquipe[[#This Row],[Mês]]=(Configuração!$D$9),Configuração!$D$12*tbEquipe[[#This Row],[Alocação]],0)),0) -> 4014.1254
A37: A Definir - ANALISTA DE NEGOCIOS SR | B37: =IFERROR(VLOOKUP(tbEquipe[[#This Row],[Nome]],tbFOPAG[[Nome]:[Cargo]],2,0),"<Selecionar Nome>") -> ANALISTA DE NEGOCIOS SR | C37: Direto | D37: 6 | E37: =176*tbEquipe[[#This Row],[Alocação]] -> 38.72 | F37: 0.22 | G37: =IFERROR((VLOOKUP(tbEquipe[[#This Row],[Nome]],tbFOPAG[[Nome]:[Custo Total]],3,0)*tbEquipe[[#This Row],[Alocação]]*IF(OR(tbEquipe[[#This Row],[Mês]]>Configuração!$D$7,tbEquipe[[#This Row],[Mês]]=Configuração!$D$7),(1+Configuração!$D$4),1))*IF(OR(tbEquipe[[#This Row],[Mês]]>Configuração!$D$8,tbEquipe[[#This Row],[Mês]]=Configuração!$D$8),(1+Configuração!$D$4),1)+(IF(tbEquipe[[#This Row],[Mês]]=(Configuração!$D$7-1),Configuração!$D$11*tbEquipe[[#This Row],[Alocação]],0))+(IF(tbEquipe[[#This Row],[Mês]]=(Configuração!$D$9),Configuração!$D$12*tbEquipe[[#This Row],[Alocação]],0)),0) -> 4014.1254
A38: A Definir - ANALISTA DE NEGOCIOS SR | B38: =IFERROR(VLOOKUP(tbEquipe[[#This Row],[Nome]],tbFOPAG[[Nome]:[Cargo]],2,0),"<Selecionar Nome>") -> ANALISTA DE NEGOCIOS SR | C38: Direto | D38: 7 | E38: =176*tbEquipe[[#This Row],[Alocação]] -> 38.72 | F38: 0.22 | G38: =IFERROR((VLOOKUP(tbEquipe[[#This Row],[Nome]],tbFOPAG[[Nome]:[Custo Total]],3,0)*tbEquipe[[#This Row],[Alocação]]*IF(OR(tbEquipe[[#This Row],[Mês]]>Configuração!$D$7,tbEquipe[[#This Row],[Mês]]=Configuração!$D$7),(1+Configuração!$D$4),1))*IF(OR(tbEquipe[[#This Row],[Mês]]>Configuração!$D$8,tbEquipe[[#This Row],[Mês]]=Configuração!$D$8),(1+Configuração!$D$4),1)+(IF(tbEquipe[[#This Row],[Mês]]=(Configuração!$D$7-1),Configuração!$D$11*tbEquipe[[#This Row],[Alocação]],0))+(IF(tbEquipe[[#This Row],[Mês]]=(Configuração!$D$9),Configuração!$D$12*tbEquipe[[#This Row],[Alocação]],0)),0) -> 4014.1254
A39: A Definir - ANALISTA DE NEGOCIOS SR | B39: =IFERROR(VLOOKUP(tbEquipe[[#This Row],[Nome]],tbFOPAG[[Nome]:[Cargo]],2,0),"<Selecionar Nome>") -> ANALISTA DE NEGOCIOS SR | C39: Direto | D39: 8 | E39: =176*tbEquipe[[#This Row],[Alocação]] -> 38.72 | F39: 0.22 | G39: =IFERROR((VLOOKUP(tbEquipe[[#This Row],[Nome]],tbFOPAG[[Nome]:[Custo Total]],3,0)*tbEquipe[[#This Row],[Alocação]]*IF(OR(tbEquipe[[#This Row],[Mês]]>Configuração!$D$7,tbEquipe[[#This Row],[Mês]]=Configuração!$D$7),(1+Configuração!$D$4),1))*IF(OR(tbEquipe[[#This Row],[Mês]]>Configuração!$D$8,tbEquipe[[#This Row],[Mês]]=Configuração!$D$8),(1+Configuração!$D$4),1)+(IF(tbEquipe[[#This Row],[Mês]]=(Configuração!$D$7-1),Configuração!$D$11*tbEquipe[[#This Row],[Alocação]],0))+(IF(tbEquipe[[#This Row],[Mês]]=(Configuração!$D$9),Configuração!$D$12*tbEquipe[[#This Row],[Alocação]],0)),0) -> 4014.1254 | I39: =SUM(G32:G39) -> 31962.789 | J39: =SUM(F32:F39) -> 1.76 | K39: =J39/12 -> 0.14666667 | M39: 2.64 | N39: 0.22
A40: A Definir - ANALISTA DE NEGOCIOS SR | B40: =IFERROR(VLOOKUP(tbEquipe[[#This Row],[Nome]],tbFOPAG[[Nome]:[Cargo]],2,0),"<Selecionar Nome>") -> ANALISTA DE NEGOCIOS SR | C40: Direto | D40: 9 | E40: =176*tbEquipe[[#This Row],[Alocação]] -> 38.72 | F40: 0.22 | G40: =IFERROR((VLOOKUP(tbEquipe[[#This Row],[Nome]],tbFOPAG[[Nome]:[Custo Total]],3,0)*tbEquipe[[#This Row],[Alocação]]*IF(OR(tbEquipe[[#This Row],[Mês]]>Configuração!$D$7,tbEquipe[[#This Row],[Mês]]=Configuração!$D$7),(1+Configuração!$D$4),1))*IF(OR(tbEquipe[[#This Row],[Mês]]>Configuração!$D$8,tbEquipe[[#This Row],[Mês]]=Configuração!$D$8),(1+Configuração!$D$4),1)+(IF(tbEquipe[[#This Row],[Mês]]=(Configuração!$D$7-1),Configuração!$D$11*tbEquipe[[#This Row],[Alocação]],0))+(IF(tbEquipe[[#This Row],[Mês]]=(Configuração!$D$9),Configuração!$D$12*tbEquipe[[#This Row],[Alocação]],0)),0) -> 4014.1254
...

Sheet Rubrica
A1: Rubrica | B1: Descrição | C1: Justificativa | D1: Mês | E1: Quantidade | F1: Custo Unitário | G1: Frete | H1: Custo Total | I1: Observações | J1: Coluna1
A2: Máquinas e Equipamentos | D2: 1 | E2: 1 | F2: =SERVICO!N10-F8+tbRubrica[[#This Row],[Coluna1]] -> 340084.8 | H2: =E2*F2 -> 340084.8 | J2: 250000
A3: Material de Consumo | D3: 2 | E3: 1 | F3: =SERVICO!N15 -> 720254.41 | H3: =E3*F3 -> 720254.41
A4: Serviço Técnico de Terceiros | D4: 3 | E4: 1 | F4: =SERVICO!N14-250000 -> 390226.14 | H4: =E4*F4 -> 390226.14 | J4: -250000
